Workbook
Name Yr_Cur: Control!$C$6
Name Yr_Prev: Control!$C$7
Name Sel_Market: Control!$C$8
Name Market_List: OFFSET(Control!$E$6,0,0,COUNTA(Control!$E$6:$E$45),1)
Name Market_Entry: OFFSET(Control!$E$7,0,0,MAX(1,COUNTA(Control!$E$7:$E$45)),1)
Name Dat_A: Data!$A$6:$A$505
Name Dat_B: Data!$B$6:$B$505
Name Dat_C: Data!$C$6:$C$505
Name Dat_D: Data!$D$6:$D$505
Name Dat_E: Data!$E$6:$E$505
Name Dat_F: Data!$F$6:$F$505
Name Dat_G: Data!$G$6:$G$505
Name Dat_H: Data!$H$6:$H$505
Name Dat_I: Data!$I$6:$I$505
Name Dat_J: Data!$J$6:$J$505
Name Dat_K: Data!$K$6:$K$505
Name Dat_L: Data!$L$6:$L$505
Name Dat_M: Data!$M$6:$M$505
Name Dat_N: Data!$N$6:$N$505
Name Dat_O: Data!$O$6:$O$505
Name Dat_P: Data!$P$6:$P$505
Name Dat_Q: Data!$Q$6:$Q$505
Name Dat_R: Data!$R$6:$R$505
Name Dat_S: Data!$S$6:$S$505

Sheet Control
B2: Advent Calendar Sales — control panel
B3: Change the yellow-blue input cells; every slide sheet updates automatically.
E4: Type your markets here (one per row)
B5: SETTINGS | E5: MARKETS | G5: HOW TO UPDATE
B6: Current year | C6: 2026 | E6: All markets | G6: 1. Go to the Data sheet. For each market × product × year add one row (or overwrite the numbers on an existing row).
B7: Comparison year | C7: =C6-1 | E7: Market A | G7: 2. Fill Launch date (blank row = product not sold in that market that year), Data through (the cut-off date of the numbers), Units and Revenue (€, cumulative from launch to the cut-off).
B8: Market | C8: All markets | G8: 3. Enter the comparison-year numbers to the same calendar date (e.g. 9 Oct 2025 next to 9 Oct 2026).
G9: 4. New market? Add its name in the MARKETS list (left), then pick it in Data column A.
B10: PRODUCTS IN SCOPE | G10: 5. Pick the Market and the products in scope on this sheet. 'All markets' adds up only markets/products that have rows for BOTH years.
B11: 24-day | C11: Yes | G11: 6. Look at the sheets 1 Cover … 5 By size. Check the 'Data check' status above; fix any row flagged in Data column S.
B12: 12-day | C12: Yes | G12: NOTE: Equal-days estimate = comparison-year × (days selling this year ÷ days selling last year), done market by market, assuming an even daily rate. Head-start value = comparison-year × (extra days ÷ days selling last year).
B13: Refill | C13: No | G13: NOTE: Fonts: install 'Barlow' and 'Barlow Condensed' (free, Google Fonts) for the intended look; otherwise Excel substitutes.
B14: (product names are fixed — do not rename) | G14: NOTE: Needs Excel 2019 / Microsoft 365 (uses MAXIFS / MINIFS).
B16: STATUS
B17: Data check | C17: =IF(COUNTIF(Dat_S,"?*")-COUNTIF(Dat_S,"OK")=0,"All rows OK",(COUNTIF(Dat_S,"?*")-COUNTIF(Dat_S,"OK"))&" row(s) need attention (Data col S)")
B18: Report date (latest cut-off) | C18: =IF(COUNTIFS(Dat_J,"CY",Dat_L,1)=0,"no data",_xlfn.MAXIFS(Dat_E,Dat_J,"CY",Dat_L,1))
B19: Rows used in comparison | C19: =COUNTIF(Dat_L,1)

Sheet Data
A1: Sales data — one row per market × product × year
A2: Blue columns = you type. Grey columns = calculated. Numbers are cumulative from launch to 'Data through'. Leave a product out (or the launch date blank) if it was not on sale in that market that year. Rows 6–505 are ready to use.
A3: Years other than Current/Comparison year are kept as history and ignored.
A5: Market | B5: Product | C5: Year | D5: Launch date | E5: Data through | F5: Units | G5: Revenue (€) | H5: Selling days | I5: Avg price (€) | J5: Role | K5: Days other yr | L5: In comparison | M5: Days CY | N5: Days PY | O5: Units eq-days | P5: Rev eq-days | Q5: Head-start units | R5: Head-start rev | S5: Row check
A6: Market A | B6: 24-day | C6: 2025 | D6: 45906 | E6: 45939 | F6: 711 | G6: 76876 | H6: =IF(AND(ISNUMBER(D6),ISNUMBER(E6)),E6-D6+1,"") | I6: =IF(AND(ISNUMBER(F6),N(F6)>0,ISNUMBER(G6)),G6/F6,"") | J6: =IF(OR(A6="",B6=""),"",IF(C6=Yr_Cur,"CY",IF(C6=Yr_Prev,"PY",""))) | K6: =IF(J6="","",IF(J6="CY",SUMIFS(Dat_H,Dat_A,A6,Dat_B,B6,Dat_C,Yr_Prev),SUMIFS(Dat_H,Dat_A,A6,Dat_B,B6,Dat_C,Yr_Cur))) | L6: =IF(J6="",0,IF(AND(ISNUMBER(H6),N(K6)>0,ISNUMBER(F6),ISNUMBER(G6),OR(Sel_Market="All markets",A6=Sel_Market),COUNTIFS(Control!$B$11:$B$13,B6,Control!$C$11:$C$13,"Yes")>0),1,0)) | M6: =IF(L6=1,IF(J6="CY",H6,K6),"") | N6: =IF(L6=1,IF(J6="PY",H6,K6),"") | O6: =IF(L6=1,IF(J6="PY",F6*M6/N6,F6),0) | P6: =IF(L6=1,IF(J6="PY",G6*M6/N6,G6),0) | Q6: =IF(AND(L6=1,J6="PY"),F6*(N6-M6)/N6,0) | R6: =IF(AND(L6=1,J6="PY"),G6*(N6-M6)/N6,0) | S6: =IF(COUNTA(A6:G6)=0,"",IF(OR(A6="",B6="",NOT(ISNUMBER(C6))),"Fill market, product and year",IF(COUNTIF(Control!$B$11:$B$13,B6)=0,"Unknown product",IF(COUNTIFS(Dat_A,A6,Dat_B,B6,Dat_C,C6)>1,"Duplicate market/product/year",IF(OR(NOT(ISNUMBER(D6)),NOT(ISNUMBER(E6))),"Add launch date and Data through date",IF(E6<D6,"Data through is before launch",IF(OR(NOT(ISNUMBER(F6)),NOT(ISNUMBER(G6))),"Add units and revenue","OK")))))))
A7: Market A | B7: 12-day | C7: 2025 | D7: 45906 | E7: 45939 | F7: 52 | G7: 3572 | H7: =IF(AND(ISNUMBER(D7),ISNUMBER(E7)),E7-D7+1,"") | I7: =IF(AND(ISNUMBER(F7),N(F7)>0,ISNUMBER(G7)),G7/F7,"") | J7: =IF(OR(A7="",B7=""),"",IF(C7=Yr_Cur,"CY",IF(C7=Yr_Prev,"PY",""))) | K7: =IF(J7="","",IF(J7="CY",SUMIFS(Dat_H,Dat_A,A7,Dat_B,B7,Dat_C,Yr_Prev),SUMIFS(Dat_H,Dat_A,A7,Dat_B,B7,Dat_C,Yr_Cur))) | L7: =IF(J7="",0,IF(AND(ISNUMBER(H7),N(K7)>0,ISNUMBER(F7),ISNUMBER(G7),OR(Sel_Market="All markets",A7=Sel_Market),COUNTIFS(Control!$B$11:$B$13,B7,Control!$C$11:$C$13,"Yes")>0),1,0)) | M7: =IF(L7=1,IF(J7="CY",H7,K7),"") | N7: =IF(L7=1,IF(J7="PY",H7,K7),"") | O7: =IF(L7=1,IF(J7="PY",F7*M7/N7,F7),0) | P7: =IF(L7=1,IF(J7="PY",G7*M7/N7,G7),0) | Q7: =IF(AND(L7=1,J7="PY"),F7*(N7-M7)/N7,0) | R7: =IF(AND(L7=1,J7="PY"),G7*(N7-M7)/N7,0) | S7: =IF(COUNTA(A7:G7)=0,"",IF(OR(A7="",B7="",NOT(ISNUMBER(C7))),"Fill market, product and year",IF(COUNTIF(Control!$B$11:$B$13,B7)=0,"Unknown product",IF(COUNTIFS(Dat_A,A7,Dat_B,B7,Dat_C,C7)>1,"Duplicate market/product/year",IF(OR(NOT(ISNUMBER(D7)),NOT(ISNUMBER(E7))),"Add launch date and Data through date",IF(E7<D7,"Data through is before launch",IF(OR(NOT(ISNUMBER(F7)),NOT(ISNUMBER(G7))),"Add units and revenue","OK")))))))
A8: Market A | B8: 24-day | C8: 2026 | D8: 46276 | E8: 46304 | F8: 398 | G8: 53563 | H8: =IF(AND(ISNUMBER(D8),ISNUMBER(E8)),E8-D8+1,"") | I8: =IF(AND(ISNUMBER(F8),N(F8)>0,ISNUMBER(G8)),G8/F8,"") | J8: =IF(OR(A8="",B8=""),"",IF(C8=Yr_Cur,"CY",IF(C8=Yr_Prev,"PY",""))) | K8: =IF(J8="","",IF(J8="CY",SUMIFS(Dat_H,Dat_A,A8,Dat_B,B8,Dat_C,Yr_Prev),SUMIFS(Dat_H,Dat_A,A8,Dat_B,B8,Dat_C,Yr_Cur))) | L8: =IF(J8="",0,IF(AND(ISNUMBER(H8),N(K8)>0,ISNUMBER(F8),ISNUMBER(G8),OR(Sel_Market="All markets",A8=Sel_Market),COUNTIFS(Control!$B$11:$B$13,B8,Control!$C$11:$C$13,"Yes")>0),1,0)) | M8: =IF(L8=1,IF(J8="CY",H8,K8),"") | N8: =IF(L8=1,IF(J8="PY",H8,K8),"") | O8: =IF(L8=1,IF(J8="PY",F8*M8/N8,F8),0) | P8: =IF(L8=1,IF(J8="PY",G8*M8/N8,G8),0) | Q8: =IF(AND(L8=1,J8="PY"),F8*(N8-M8)/N8,0) | R8: =IF(AND(L8=1,J8="PY"),G8*(N8-M8)/N8,0) | S8: =IF(COUNTA(A8:G8)=0,"",IF(OR(A8="",B8="",NOT(ISNUMBER(C8))),"Fill market, product and year",IF(COUNTIF(Control!$B$11:$B$13,B8)=0,"Unknown product",IF(COUNTIFS(Dat_A,A8,Dat_B,B8,Dat_C,C8)>1,"Duplicate market/product/year",IF(OR(NOT(ISNUMBER(D8)),NOT(ISNUMBER(E8))),"Add launch date and Data through date",IF(E8<D8,"Data through is before launch",IF(OR(NOT(ISNUMBER(F8)),NOT(ISNUMBER(G8))),"Add units and revenue","OK")))))))
A9: Market A | B9: 12-day | C9: 2026 | D9: 46276 | E9: 46304 | F9: 54 | G9: 3896 | H9: =IF(AND(ISNUMBER(D9),ISNUMBER(E9)),E9-D9+1,"") | I9: =IF(AND(ISNUMBER(F9),N(F9)>0,ISNUMBER(G9)),G9/F9,"") | J9: =IF(OR(A9="",B9=""),"",IF(C9=Yr_Cur,"CY",IF(C9=Yr_Prev,"PY",""))) | K9: =IF(J9="","",IF(J9="CY",SUMIFS(Dat_H,Dat_A,A9,Dat_B,B9,Dat_C,Yr_Prev),SUMIFS(Dat_H,Dat_A,A9,Dat_B,B9,Dat_C,Yr_Cur))) | L9: =IF(J9="",0,IF(AND(ISNUMBER(H9),N(K9)>0,ISNUMBER(F9),ISNUMBER(G9),OR(Sel_Market="All markets",A9=Sel_Market),COUNTIFS(Control!$B$11:$B$13,B9,Control!$C$11:$C$13,"Yes")>0),1,0)) | M9: =IF(L9=1,IF(J9="CY",H9,K9),"") | N9: =IF(L9=1,IF(J9="PY",H9,K9),"") | O9: =IF(L9=1,IF(J9="PY",F9*M9/N9,F9),0) | P9: =IF(L9=1,IF(J9="PY",G9*M9/N9,G9),0) | Q9: =IF(AND(L9=1,J9="PY"),F9*(N9-M9)/N9,0) | R9: =IF(AND(L9=1,J9="PY"),G9*(N9-M9)/N9,0) | S9: =IF(COUNTA(A9:G9)=0,"",IF(OR(A9="",B9="",NOT(ISNUMBER(C9))),"Fill market, product and year",IF(COUNTIF(Control!$B$11:$B$13,B9)=0,"Unknown product",IF(COUNTIFS(Dat_A,A9,Dat_B,B9,Dat_C,C9)>1,"Duplicate market/product/year",IF(OR(NOT(ISNUMBER(D9)),NOT(ISNUMBER(E9))),"Add launch date and Data through date",IF(E9<D9,"Data through is before launch",IF(OR(NOT(ISNUMBER(F9)),NOT(ISNUMBER(G9))),"Add units and revenue","OK")))))))
H10: =IF(AND(ISNUMBER(D10),ISNUMBER(E10)),E10-D10+1,"") | I10: =IF(AND(ISNUMBER(F10),N(F10)>0,ISNUMBER(G10)),G10/F10,"") | J10: =IF(OR(A10="",B10=""),"",IF(C10=Yr_Cur,"CY",IF(C10=Yr_Prev,"PY",""))) | K10: =IF(J10="","",IF(J10="CY",SUMIFS(Dat_H,Dat_A,A10,Dat_B,B10,Dat_C,Yr_Prev),SUMIFS(Dat_H,Dat_A,A10,Dat_B,B10,Dat_C,Yr_Cur))) | L10: =IF(J10="",0,IF(AND(ISNUMBER(H10),N(K10)>0,ISNUMBER(F10),ISNUMBER(G10),OR(Sel_Market="All markets",A10=Sel_Market),COUNTIFS(Control!$B$11:$B$13,B10,Control!$C$11:$C$13,"Yes")>0),1,0)) | M10: =IF(L10=1,IF(J10="CY",H10,K10),"") | N10: =IF(L10=1,IF(J10="PY",H10,K10),"") | O10: =IF(L10=1,IF(J10="PY",F10*M10/N10,F10),0) | P10: =IF(L10=1,IF(J10="PY",G10*M10/N10,G10),0) | Q10: =IF(AND(L10=1,J10="PY"),F10*(N10-M10)/N10,0) | R10: =IF(AND(L10=1,J10="PY"),G10*(N10-M10)/N10,0) | S10: =IF(COUNTA(A10:G10)=0,"",IF(OR(A10="",B10="",NOT(ISNUMBER(C10))),"Fill market, product and year",IF(COUNTIF(Control!$B$11:$B$13,B10)=0,"Unknown product",IF(COUNTIFS(Dat_A,A10,Dat_B,B10,Dat_C,C10)>1,"Duplicate market/product/year",IF(OR(NOT(ISNUMBER(D10)),NOT(ISNUMBER(E10))),"Add launch date and Data through date",IF(E10<D10,"Data through is before launch",IF(OR(NOT(ISNUMBER(F10)),NOT(ISNUMBER(G10))),"Add units and revenue","OK")))))))
H11: =IF(AND(ISNUMBER(D11),ISNUMBER(E11)),E11-D11+1,"") | I11: =IF(AND(ISNUMBER(F11),N(F11)>0,ISNUMBER(G11)),G11/F11,"") | J11: =IF(OR(A11="",B11=""),"",IF(C11=Yr_Cur,"CY",IF(C11=Yr_Prev,"PY",""))) | K11: =IF(J11="","",IF(J11="CY",SUMIFS(Dat_H,Dat_A,A11,Dat_B,B11,Dat_C,Yr_Prev),SUMIFS(Dat_H,Dat_A,A11,Dat_B,B11,Dat_C,Yr_Cur))) | L11: =IF(J11="",0,IF(AND(ISNUMBER(H11),N(K11)>0,ISNUMBER(F11),ISNUMBER(G11),OR(Sel_Market="All markets",A11=Sel_Market),COUNTIFS(Control!$B$11:$B$13,B11,Control!$C$11:$C$13,"Yes")>0),1,0)) | M11: =IF(L11=1,IF(J11="CY",H11,K11),"") | N11: =IF(L11=1,IF(J11="PY",H11,K11),"") | O11: =IF(L11=1,IF(J11="PY",F11*M11/N11,F11),0) | P11: =IF(L11=1,IF(J11="PY",G11*M11/N11,G11),0) | Q11: =IF(AND(L11=1,J11="PY"),F11*(N11-M11)/N11,0) | R11: =IF(AND(L11=1,J11="PY"),G11*(N11-M11)/N11,0) | S11: =IF(COUNTA(A11:G11)=0,"",IF(OR(A11="",B11="",NOT(ISNUMBER(C11))),"Fill market, product and year",IF(COUNTIF(Control!$B$11:$B$13,B11)=0,"Unknown product",IF(COUNTIFS(Dat_A,A11,Dat_B,B11,Dat_C,C11)>1,"Duplicate market/product/year",IF(OR(NOT(ISNUMBER(D11)),NOT(ISNUMBER(E11))),"Add launch date and Data through date",IF(E11<D11,"Data through is before launch",IF(OR(NOT(ISNUMBER(F11)),NOT(ISNUMBER(G11))),"Add units and revenue","OK")))))))
H12: =IF(AND(ISNUMBER(D12),ISNUMBER(E12)),E12-D12+1,"") | I12: =IF(AND(ISNUMBER(F12),N(F12)>0,ISNUMBER(G12)),G12/F12,"") | J12: =IF(OR(A12="",B12=""),"",IF(C12=Yr_Cur,"CY",IF(C12=Yr_Prev,"PY",""))) | K12: =IF(J12="","",IF(J12="CY",SUMIFS(Dat_H,Dat_A,A12,Dat_B,B12,Dat_C,Yr_Prev),SUMIFS(Dat_H,Dat_A,A12,Dat_B,B12,Dat_C,Yr_Cur))) | L12: =IF(J12="",0,IF(AND(ISNUMBER(H12),N(K12)>0,ISNUMBER(F12),ISNUMBER(G12),OR(Sel_Market="All markets",A12=Sel_Market),COUNTIFS(Control!$B$11:$B$13,B12,Control!$C$11:$C$13,"Yes")>0),1,0)) | M12: =IF(L12=1,IF(J12="CY",H12,K12),"") | N12: =IF(L12=1,IF(J12="PY",H12,K12),"") | O12: =IF(L12=1,IF(J12="PY",F12*M12/N12,F12),0) | P12: =IF(L12=1,IF(J12="PY",G12*M12/N12,G12),0) | Q12: =IF(AND(L12=1,J12="PY"),F12*(N12-M12)/N12,0) | R12: =IF(AND(L12=1,J12="PY"),G12*(N12-M12)/N12,0) | S12: =IF(COUNTA(A12:G12)=0,"",IF(OR(A12="",B12="",NOT(ISNUMBER(C12))),"Fill market, product and year",IF(COUNTIF(Control!$B$11:$B$13,B12)=0,"Unknown product",IF(COUNTIFS(Dat_A,A12,Dat_B,B12,Dat_C,C12)>1,"Duplicate market/product/year",IF(OR(NOT(ISNUMBER(D12)),NOT(ISNUMBER(E12))),"Add launch date and Data through date",IF(E12<D12,"Data through is before launch",IF(OR(NOT(ISNUMBER(F12)),NOT(ISNUMBER(G12))),"Add units and revenue","OK")))))))
H13: =IF(AND(ISNUMBER(D13),ISNUMBER(E13)),E13-D13+1,"") | I13: =IF(AND(ISNUMBER(F13),N(F13)>0,ISNUMBER(G13)),G13/F13,"") | J13: =IF(OR(A13="",B13=""),"",IF(C13=Yr_Cur,"CY",IF(C13=Yr_Prev,"PY",""))) | K13: =IF(J13="","",IF(J13="CY",SUMIFS(Dat_H,Dat_A,A13,Dat_B,B13,Dat_C,Yr_Prev),SUMIFS(Dat_H,Dat_A,A13,Dat_B,B13,Dat_C,Yr_Cur))) | L13: =IF(J13="",0,IF(AND(ISNUMBER(H13),N(K13)>0,ISNUMBER(F13),ISNUMBER(G13),OR(Sel_Market="All markets",A13=Sel_Market),COUNTIFS(Control!$B$11:$B$13,B13,Control!$C$11:$C$13,"Yes")>0),1,0)) | M13: =IF(L13=1,IF(J13="CY",H13,K13),"") | N13: =IF(L13=1,IF(J13="PY",H13,K13),"") | O13: =IF(L13=1,IF(J13="PY",F13*M13/N13,F13),0) | P13: =IF(L13=1,IF(J13="PY",G13*M13/N13,G13),0) | Q13: =IF(AND(L13=1,J13="PY"),F13*(N13-M13)/N13,0) | R13: =IF(AND(L13=1,J13="PY"),G13*(N13-M13)/N13,0) | S13: =IF(COUNTA(A13:G13)=0,"",IF(OR(A13="",B13="",NOT(ISNUMBER(C13))),"Fill market, product and year",IF(COUNTIF(Control!$B$11:$B$13,B13)=0,"Unknown product",IF(COUNTIFS(Dat_A,A13,Dat_B,B13,Dat_C,C13)>1,"Duplicate market/product/year",IF(OR(NOT(ISNUMBER(D13)),NOT(ISNUMBER(E13))),"Add launch date and Data through date",IF(E13<D13,"Data through is before launch",IF(OR(NOT(ISNUMBER(F13)),NOT(ISNUMBER(G13))),"Add units and revenue","OK")))))))
H14: =IF(AND(ISNUMBER(D14),ISNUMBER(E14)),E14-D14+1,"") | I14: =IF(AND(ISNUMBER(F14),N(F14)>0,ISNUMBER(G14)),G14/F14,"") | J14: =IF(OR(A14="",B14=""),"",IF(C14=Yr_Cur,"CY",IF(C14=Yr_Prev,"PY",""))) | K14: =IF(J14="","",IF(J14="CY",SUMIFS(Dat_H,Dat_A,A14,Dat_B,B14,Dat_C,Yr_Prev),SUMIFS(Dat_H,Dat_A,A14,Dat_B,B14,Dat_C,Yr_Cur))) | L14: =IF(J14="",0,IF(AND(ISNUMBER(H14),N(K14)>0,ISNUMBER(F14),ISNUMBER(G14),OR(Sel_Market="All markets",A14=Sel_Market),COUNTIFS(Control!$B$11:$B$13,B14,Control!$C$11:$C$13,"Yes")>0),1,0)) | M14: =IF(L14=1,IF(J14="CY",H14,K14),"") | N14: =IF(L14=1,IF(J14="PY",H14,K14),"") | O14: =IF(L14=1,IF(J14="PY",F14*M14/N14,F14),0) | P14: =IF(L14=1,IF(J14="PY",G14*M14/N14,G14),0) | Q14: =IF(AND(L14=1,J14="PY"),F14*(N14-M14)/N14,0) | R14: =IF(AND(L14=1,J14="PY"),G14*(N14-M14)/N14,0) | S14: =IF(COUNTA(A14:G14)=0,"",IF(OR(A14="",B14="",NOT(ISNUMBER(C14))),"Fill market, product and year",IF(COUNTIF(Control!$B$11:$B$13,B14)=0,"Unknown product",IF(COUNTIFS(Dat_A,A14,Dat_B,B14,Dat_C,C14)>1,"Duplicate market/product/year",IF(OR(NOT(ISNUMBER(D14)),NOT(ISNUMBER(E14))),"Add launch date and Data through date",IF(E14<D14,"Data through is before launch",IF(OR(NOT(ISNUMBER(F14)),NOT(ISNUMBER(G14))),"Add units and revenue","OK")))))))
H15: =IF(AND(ISNUMBER(D15),ISNUMBER(E15)),E15-D15+1,"") | I15: =IF(AND(ISNUMBER(F15),N(F15)>0,ISNUMBER(G15)),G15/F15,"") | J15: =IF(OR(A15="",B15=""),"",IF(C15=Yr_Cur,"CY",IF(C15=Yr_Prev,"PY",""))) | K15: =IF(J15="","",IF(J15="CY",SUMIFS(Dat_H,Dat_A,A15,Dat_B,B15,Dat_C,Yr_Prev),SUMIFS(Dat_H,Dat_A,A15,Dat_B,B15,Dat_C,Yr_Cur))) | L15: =IF(J15="",0,IF(AND(ISNUMBER(H15),N(K15)>0,ISNUMBER(F15),ISNUMBER(G15),OR(Sel_Market="All markets",A15=Sel_Market),COUNTIFS(Control!$B$11:$B$13,B15,Control!$C$11:$C$13,"Yes")>0),1,0)) | M15: =IF(L15=1,IF(J15="CY",H15,K15),"") | N15: =IF(L15=1,IF(J15="PY",H15,K15),"") | O15: =IF(L15=1,IF(J15="PY",F15*M15/N15,F15),0) | P15: =IF(L15=1,IF(J15="PY",G15*M15/N15,G15),0) | Q15: =IF(AND(L15=1,J15="PY"),F15*(N15-M15)/N15,0) | R15: =IF(AND(L15=1,J15="PY"),G15*(N15-M15)/N15,0) | S15: =IF(COUNTA(A15:G15)=0,"",IF(OR(A15="",B15="",NOT(ISNUMBER(C15))),"Fill market, product and year",IF(COUNTIF(Control!$B$11:$B$13,B15)=0,"Unknown product",IF(COUNTIFS(Dat_A,A15,Dat_B,B15,Dat_C,C15)>1,"Duplicate market/product/year",IF(OR(NOT(ISNUMBER(D15)),NOT(ISNUMBER(E15))),"Add launch date and Data through date",IF(E15<D15,"Data through is before launch",IF(OR(NOT(ISNUMBER(F15)),NOT(ISNUMBER(G15))),"Add units and revenue","OK")))))))
H16: =IF(AND(ISNUMBER(D16),ISNUMBER(E16)),E16-D16+1,"") | I16: =IF(AND(ISNUMBER(F16),N(F16)>0,ISNUMBER(G16)),G16/F16,"") | J16: =IF(OR(A16="",B16=""),"",IF(C16=Yr_Cur,"CY",IF(C16=Yr_Prev,"PY",""))) | K16: =IF(J16="","",IF(J16="CY",SUMIFS(Dat_H,Dat_A,A16,Dat_B,B16,Dat_C,Yr_Prev),SUMIFS(Dat_H,Dat_A,A16,Dat_B,B16,Dat_C,Yr_Cur))) | L16: =IF(J16="",0,IF(AND(ISNUMBER(H16),N(K16)>0,ISNUMBER(F16),ISNUMBER(G16),OR(Sel_Market="All markets",A16=Sel_Market),COUNTIFS(Control!$B$11:$B$13,B16,Control!$C$11:$C$13,"Yes")>0),1,0)) | M16: =IF(L16=1,IF(J16="CY",H16,K16),"") | N16: =IF(L16=1,IF(J16="PY",H16,K16),"") | O16: =IF(L16=1,IF(J16="PY",F16*M16/N16,F16),0) | P16: =IF(L16=1,IF(J16="PY",G16*M16/N16,G16),0) | Q16: =IF(AND(L16=1,J16="PY"),F16*(N16-M16)/N16,0) | R16: =IF(AND(L16=1,J16="PY"),G16*(N16-M16)/N16,0) | S16: =IF(COUNTA(A16:G16)=0,"",IF(OR(A16="",B16="",NOT(ISNUMBER(C16))),"Fill market, product and year",IF(COUNTIF(Control!$B$11:$B$13,B16)=0,"Unknown product",IF(COUNTIFS(Dat_A,A16,Dat_B,B16,Dat_C,C16)>1,"Duplicate market/product/year",IF(OR(NOT(ISNUMBER(D16)),NOT(ISNUMBER(E16))),"Add launch date and Data through date",IF(E16<D16,"Data through is before launch",IF(OR(NOT(ISNUMBER(F16)),NOT(ISNUMBER(G16))),"Add units and revenue","OK")))))))
H17: =IF(AND(ISNUMBER(D17),ISNUMBER(E17)),E17-D17+1,"") | I17: =IF(AND(ISNUMBER(F17),N(F17)>0,ISNUMBER(G17)),G17/F17,"") | J17: =IF(OR(A17="",B17=""),"",IF(C17=Yr_Cur,"CY",IF(C17=Yr_Prev,"PY",""))) | K17: =IF(J17="","",IF(J17="CY",SUMIFS(Dat_H,Dat_A,A17,Dat_B,B17,Dat_C,Yr_Prev),SUMIFS(Dat_H,Dat_A,A17,Dat_B,B17,Dat_C,Yr_Cur))) | L17: =IF(J17="",0,IF(AND(ISNUMBER(H17),N(K17)>0,ISNUMBER(F17),ISNUMBER(G17),OR(Sel_Market="All markets",A17=Sel_Market),COUNTIFS(Control!$B$11:$B$13,B17,Control!$C$11:$C$13,"Yes")>0),1,0)) | M17: =IF(L17=1,IF(J17="CY",H17,K17),"") | N17: =IF(L17=1,IF(J17="PY",H17,K17),"") | O17: =IF(L17=1,IF(J17="PY",F17*M17/N17,F17),0) | P17: =IF(L17=1,IF(J17="PY",G17*M17/N17,G17),0) | Q17: =IF(AND(L17=1,J17="PY"),F17*(N17-M17)/N17,0) | R17: =IF(AND(L17=1,J17="PY"),G17*(N17-M17)/N17,0) | S17: =IF(COUNTA(A17:G17)=0,"",IF(OR(A17="",B17="",NOT(ISNUMBER(C17))),"Fill market, product and year",IF(COUNTIF(Control!$B$11:$B$13,B17)=0,"Unknown product",IF(COUNTIFS(Dat_A,A17,Dat_B,B17,Dat_C,C17)>1,"Duplicate market/product/year",IF(OR(NOT(ISNUMBER(D17)),NOT(ISNUMBER(E17))),"Add launch date and Data through date",IF(E17<D17,"Data through is before launch",IF(OR(NOT(ISNUMBER(F17)),NOT(ISNUMBER(G17))),"Add units and revenue","OK")))))))
H18: =IF(AND(ISNUMBER(D18),ISNUMBER(E18)),E18-D18+1,"") | I18: =IF(AND(ISNUMBER(F18),N(F18)>0,ISNUMBER(G18)),G18/F18,"") | J18: =IF(OR(A18="",B18=""),"",IF(C18=Yr_Cur,"CY",IF(C18=Yr_Prev,"PY",""))) | K18: =IF(J18="","",IF(J18="CY",SUMIFS(Dat_H,Dat_A,A18,Dat_B,B18,Dat_C,Yr_Prev),SUMIFS(Dat_H,Dat_A,A18,Dat_B,B18,Dat_C,Yr_Cur))) | L18: =IF(J18="",0,IF(AND(ISNUMBER(H18),N(K18)>0,ISNUMBER(F18),ISNUMBER(G18),OR(Sel_Market="All markets",A18=Sel_Market),COUNTIFS(Control!$B$11:$B$13,B18,Control!$C$11:$C$13,"Yes")>0),1,0)) | M18: =IF(L18=1,IF(J18="CY",H18,K18),"") | N18: =IF(L18=1,IF(J18="PY",H18,K18),"") | O18: =IF(L18=1,IF(J18="PY",F18*M18/N18,F18),0) | P18: =IF(L18=1,IF(J18="PY",G18*M18/N18,G18),0) | Q18: =IF(AND(L18=1,J18="PY"),F18*(N18-M18)/N18,0) | R18: =IF(AND(L18=1,J18="PY"),G18*(N18-M18)/N18,0) | S18: =IF(COUNTA(A18:G18)=0,"",IF(OR(A18="",B18="",NOT(ISNUMBER(C18))),"Fill market, product and year",IF(COUNTIF(Control!$B$11:$B$13,B18)=0,"Unknown product",IF(COUNTIFS(Dat_A,A18,Dat_B,B18,Dat_C,C18)>1,"Duplicate market/product/year",IF(OR(NOT(ISNUMBER(D18)),NOT(ISNUMBER(E18))),"Add launch date and Data through date",IF(E18<D18,"Data through is before launch",IF(OR(NOT(ISNUMBER(F18)),NOT(ISNUMBER(G18))),"Add units and revenue","OK")))))))
H19: =IF(AND(ISNUMBER(D19),ISNUMBER(E19)),E19-D19+1,"") | I19: =IF(AND(ISNUMBER(F19),N(F19)>0,ISNUMBER(G19)),G19/F19,"") | J19: =IF(OR(A19="",B19=""),"",IF(C19=Yr_Cur,"CY",IF(C19=Yr_Prev,"PY",""))) | K19: =IF(J19="","",IF(J19="CY",SUMIFS(Dat_H,Dat_A,A19,Dat_B,B19,Dat_C,Yr_Prev),SUMIFS(Dat_H,Dat_A,A19,Dat_B,B19,Dat_C,Yr_Cur))) | L19: =IF(J19="",0,IF(AND(ISNUMBER(H19),N(K19)>0,ISNUMBER(F19),ISNUMBER(G19),OR(Sel_Market="All markets",A19=Sel_Market),COUNTIFS(Control!$B$11:$B$13,B19,Control!$C$11:$C$13,"Yes")>0),1,0)) | M19: =IF(L19=1,IF(J19="CY",H19,K19),"") | N19: =IF(L19=1,IF(J19="PY",H19,K19),"") | O19: =IF(L19=1,IF(J19="PY",F19*M19/N19,F19),0) | P19: =IF(L19=1,IF(J19="PY",G19*M19/N19,G19),0) | Q19: =IF(AND(L19=1,J19="PY"),F19*(N19-M19)/N19,0) | R19: =IF(AND(L19=1,J19="PY"),G19*(N19-M19)/N19,0) | S19: =IF(COUNTA(A19:G19)=0,"",IF(OR(A19="",B19="",NOT(ISNUMBER(C19))),"Fill market, product and year",IF(COUNTIF(Control!$B$11:$B$13,B19)=0,"Unknown product",IF(COUNTIFS(Dat_A,A19,Dat_B,B19,Dat_C,C19)>1,"Duplicate market/product/year",IF(OR(NOT(ISNUMBER(D19)),NOT(ISNUMBER(E19))),"Add launch date and Data through date",IF(E19<D19,"Data through is before launch",IF(OR(NOT(ISNUMBER(F19)),NOT(ISNUMBER(G19))),"Add units and revenue","OK")))))))
H20: =IF(AND(ISNUMBER(D20),ISNUMBER(E20)),E20-D20+1,"") | I20: =IF(AND(ISNUMBER(F20),N(F20)>0,ISNUMBER(G20)),G20/F20,"") | J20: =IF(OR(A20="",B20=""),"",IF(C20=Yr_Cur,"CY",IF(C20=Yr_Prev,"PY",""))) | K20: =IF(J20="","",IF(J20="CY",SUMIFS(Dat_H,Dat_A,A20,Dat_B,B20,Dat_C,Yr_Prev),SUMIFS(Dat_H,Dat_A,A20,Dat_B,B20,Dat_C,Yr_Cur))) | L20: =IF(J20="",0,IF(AND(ISNUMBER(H20),N(K20)>0,ISNUMBER(F20),ISNUMBER(G20),OR(Sel_Market="All markets",A20=Sel_Market),COUNTIFS(Control!$B$11:$B$13,B20,Control!$C$11:$C$13,"Yes")>0),1,0)) | M20: =IF(L20=1,IF(J20="CY",H20,K20),"") | N20: =IF(L20=1,IF(J20="PY",H20,K20),"") | O20: =IF(L20=1,IF(J20="PY",F20*M20/N20,F20),0) | P20: =IF(L20=1,IF(J20="PY",G20*M20/N20,G20),0) | Q20: =IF(AND(L20=1,J20="PY"),F20*(N20-M20)/N20,0) | R20: =IF(AND(L20=1,J20="PY"),G20*(N20-M20)/N20,0) | S20: =IF(COUNTA(A20:G20)=0,"",IF(OR(A20="",B20="",NOT(ISNUMBER(C20))),"Fill market, product and year",IF(COUNTIF(Control!$B$11:$B$13,B20)=0,"Unknown product",IF(COUNTIFS(Dat_A,A20,Dat_B,B20,Dat_C,C20)>1,"Duplicate market/product/year",IF(OR(NOT(ISNUMBER(D20)),NOT(ISNUMBER(E20))),"Add launch date and Data through date",IF(E20<D20,"Data through is before launch",IF(OR(NOT(ISNUMBER(F20)),NOT(ISNUMBER(G20))),"Add units and revenue","OK")))))))
H21: =IF(AND(ISNUMBER(D21),ISNUMBER(E21)),E21-D21+1,"") | I21: =IF(AND(ISNUMBER(F21),N(F21)>0,ISNUMBER(G21)),G21/F21,"") | J21: =IF(OR(A21="",B21=""),"",IF(C21=Yr_Cur,"CY",IF(C21=Yr_Prev,"PY",""))) | K21: =IF(J21="","",IF(J21="CY",SUMIFS(Dat_H,Dat_A,A21,Dat_B,B21,Dat_C,Yr_Prev),SUMIFS(Dat_H,Dat_A,A21,Dat_B,B21,Dat_C,Yr_Cur))) | L21: =IF(J21="",0,IF(AND(ISNUMBER(H21),N(K21)>0,ISNUMBER(F21),ISNUMBER(G21),OR(Sel_Market="All markets",A21=Sel_Market),COUNTIFS(Control!$B$11:$B$13,B21,Control!$C$11:$C$13,"Yes")>0),1,0)) | M21: =IF(L21=1,IF(J21="CY",H21,K21),"") | N21: =IF(L21=1,IF(J21="PY",H21,K21),"") | O21: =IF(L21=1,IF(J21="PY",F21*M21/N21,F21),0) | P21: =IF(L21=1,IF(J21="PY",G21*M21/N21,G21),0) | Q21: =IF(AND(L21=1,J21="PY"),F21*(N21-M21)/N21,0) | R21: =IF(AND(L21=1,J21="PY"),G21*(N21-M21)/N21,0) | S21: =IF(COUNTA(A21:G21)=0,"",IF(OR(A21="",B21="",NOT(ISNUMBER(C21))),"Fill market, product and year",IF(COUNTIF(Control!$B$11:$B$13,B21)=0,"Unknown product",IF(COUNTIFS(Dat_A,A21,Dat_B,B21,Dat_C,C21)>1,"Duplicate market/product/year",IF(OR(NOT(ISNUMBER(D21)),NOT(ISNUMBER(E21))),"Add launch date and Data through date",IF(E21<D21,"Data through is before launch",IF(OR(NOT(ISNUMBER(F21)),NOT(ISNUMBER(G21))),"Add units and revenue","OK")))))))
... H505: =IF(AND(ISNUMBER(D505),ISNUMBER(E505)),E505-D505+1,"") | I505: =IF(AND(ISNUMBER(F505),N(F505)>0,ISNUMBER(G505)),G505/F505,"") | J505: =IF(OR(A505="",B505=""),"",IF(C505=Yr_Cur,"CY",IF(C505=Yr_Prev,"PY",""))) | K505: =IF(J505="","",IF(J505="CY",SUMIFS(Dat_H,Dat_A,A505,Dat_B,B505,Dat_C,Yr_Prev),SUMIFS(Dat_H,Dat_A,A505,Dat_B,B505,Dat_C,Yr_Cur))) | L505: =IF(J505="",0,IF(AND(ISNUMBER(H505),N(K505)>0,ISNUMBER(F505),ISNUMBER(G505),OR(Sel_Market="All markets",A505=Sel_Market),COUNTIFS(Control!$B$11:$B$13,B505,Control!$C$11:$C$13,"Yes")>0),1,0)) | M505: =IF(L505=1,IF(J505="CY",H505,K505),"") | N505: =IF(L505=1,IF(J505="PY",H505,K505),"") | O505: =IF(L505=1,IF(J505="PY",F505*M505/N505,F505),0) | P505: =IF(L505=1,IF(J505="PY",G505*M505/N505,G505),0) | Q505: =IF(AND(L505=1,J505="PY"),F505*(N505-M505)/N505,0) | R505: =IF(AND(L505=1,J505="PY"),G505*(N505-M505)/N505,0) | S505: =IF(COUNTA(A505:G505)=0,"",IF(OR(A505="",B505="",NOT(ISNUMBER(C505))),"Fill market, product and year",IF(COUNTIF(Control!$B$11:$B$13,B505)=0,"Unknown product",IF(COUNTIFS(Dat_A,A505,Dat_B,B505,Dat_C,C505)>1,"Duplicate market/product/year",IF(OR(NOT(ISNUMBER(D505)),NOT(ISNUMBER(E505))),"Add launch date and Data through date",IF(E505<D505,"Data through is before launch",IF(OR(NOT(ISNUMBER(F505)),NOT(ISNUMBER(G505))),"Add units and revenue","OK")))))))

Sheet 1 Cover
E4: =Calc!$B$41 | AM4: =Calc!$B$40
E12: Advent Calendar Sales
E21: =Calc!$B$42
E30: =Calc!$B$43 | V30: =Calc!$B$44 | AM30: =Calc!$B$45

Sheet 2 Summary
E3: =Calc!$B$46 | AM3: ="MARKET: "&UPPER(Calc!$B$23)
E4: =Calc!$B$47
D10: + | U10: + | V10: + | AM10: + | AN10: + | BE10: +
F12: Total | X12: =Calc!$A$6 | AP12: =Calc!$A$7
F14: =IF(Calc!$B$9=1,Calc!$D$9,"–") | X14: =IF(Calc!$B$6=1,Calc!$D$6,"–") | AP14: =IF(Calc!$B$7=1,Calc!$D$7,"–")
F18: =IF(Calc!$B$9=1,Calc!$L$9,"–") | K18: same date | X18: =IF(Calc!$B$6=1,Calc!$L$6,"–") | AC18: same date | AP18: =IF(Calc!$B$7=1,Calc!$L$7,"–") | AU18: same date
F19: =IF(Calc!$B$9=1,Calc!$N$9,"–") | K19: equal days | X19: =IF(Calc!$B$6=1,Calc!$N$6,"–") | AC19: equal days | AP19: =IF(Calc!$B$7=1,Calc!$N$7,"–") | AU19: equal days
F21: =IF(Calc!$B$9=1,Calc!$C$9,"–") | X21: =IF(Calc!$B$6=1,Calc!$C$6,"–") | AP21: =IF(Calc!$B$7=1,Calc!$C$7,"–")
F24: =IF(Calc!$B$9=1,Calc!$K$9,"–") | K24: same date | X24: =IF(Calc!$B$6=1,Calc!$K$6,"–") | AC24: ="units vs "&Yr_Prev | AP24: =IF(Calc!$B$7=1,Calc!$K$7,"–") | AU24: ="units vs "&Yr_Prev
F25: =IF(Calc!$B$9=1,Calc!$M$9,"–") | K25: equal days | X25: =IF(Calc!$B$6=1,Calc!$Q$6,"–") | AC25: avg price | AP25: =IF(Calc!$B$7=1,Calc!$Q$7,"–") | AU25: avg price
D29: + | U29: + | V29: + | AM29: + | AN29: + | BE29: +
F31: =Calc!$B$54 | X31: =Calc!$B$55

Sheet 3 Launch timing
E3: =Calc!$B$51 | AM3: ="MARKET: "&UPPER(Calc!$B$23)
E4: =Calc!$B$48
D10: + | BE10: +
F22: =Calc!$B$73
D23: + | BE23: +
E25: =Calc!$B$65 | W25: =Calc!$B$66 | AO25: GAP WITHOUT HEAD START
E26: =Calc!$B$67 | W26: =Calc!$B$68 | AO26: =Calc!$B$69
E29: =Calc!$B$70 | W29: =Calc!$B$71 | AO29: =Calc!$B$72
E33: =Calc!$B$56

Sheet 4 Total
E3: =Calc!$B$52 | AM3: ="MARKET: "&UPPER(Calc!$B$23)
E4: =Calc!$B$49
D10: + | AC10: + | AF10: + | BE10: +
F12: Same calendar date | AH12: Same days since launch
F14: =Calc!$B$59 | AH14: =Calc!$B$60
F17: REVENUE | R17: UNITS | AH17: REVENUE | AT17: UNITS
F18: =IF(Calc!$B$9=1,Calc!$D$9,"–") | R18: =IF(Calc!$B$9=1,Calc!$C$9,"–") | AH18: =IF(Calc!$B$9=1,Calc!$D$9,"–") | AT18: =IF(Calc!$B$9=1,Calc!$C$9,"–")
F22: =IF(Calc!$B$9=1,Calc!$L$9,"–") | R22: =IF(Calc!$B$9=1,Calc!$K$9,"–") | AH22: =IF(Calc!$B$9=1,Calc!$N$9,"–") | AT22: =IF(Calc!$B$9=1,Calc!$M$9,"–")
F25: =Calc!$B$61 | R25: =Calc!$B$62 | AH25: =Calc!$B$63 | AT25: =Calc!$B$64
D27: + | AC27: + | AF27: + | BE27: +
E29: =Calc!$B$57

Sheet 5 By size
E3: =Calc!$B$53 | AM3: ="MARKET: "&UPPER(Calc!$B$23)
E4: =Calc!$B$50
D10: + | BE10: +
F12: SIZE | N12: ="UNITS "&Yr_Cur | T12: ="UNITS VS "&Yr_Prev | Z12: ="REVENUE "&Yr_Cur | AF12: REV. SAME DATE | AL12: REV. SAME DAYS* | AR12: AVG PRICE | AX12: ="PRICE VS "&Yr_Prev
F14: =Calc!$A$6 | N14: =IF(Calc!$B$6=1,Calc!$C$6,"–") | T14: =IF(Calc!$B$6=1,Calc!$K$6,"–") | Z14: =IF(Calc!$B$6=1,Calc!$D$6,"–") | AF14: =IF(Calc!$B$6=1,Calc!$L$6,"–") | AL14: =IF(Calc!$B$6=1,Calc!$N$6,"–") | AR14: =IF(Calc!$B$6=1,Calc!$O$6,"–") | AX14: =IF(Calc!$B$6=1,Calc!$Q$6,"–")
F17: =Calc!$A$7 | N17: =IF(Calc!$B$7=1,Calc!$C$7,"–") | T17: =IF(Calc!$B$7=1,Calc!$K$7,"–") | Z17: =IF(Calc!$B$7=1,Calc!$D$7,"–") | AF17: =IF(Calc!$B$7=1,Calc!$L$7,"–") | AL17: =IF(Calc!$B$7=1,Calc!$N$7,"–") | AR17: =IF(Calc!$B$7=1,Calc!$O$7,"–") | AX17: =IF(Calc!$B$7=1,Calc!$Q$7,"–")
F20: =Calc!$A$8 | N20: =IF(Calc!$B$8=1,Calc!$C$8,"–") | T20: =IF(Calc!$B$8=1,Calc!$K$8,"–") | Z20: =IF(Calc!$B$8=1,Calc!$D$8,"–") | AF20: =IF(Calc!$B$8=1,Calc!$L$8,"–") | AL20: =IF(Calc!$B$8=1,Calc!$N$8,"–") | AR20: =IF(Calc!$B$8=1,Calc!$O$8,"–") | AX20: =IF(Calc!$B$8=1,Calc!$Q$8,"–")
F23: Total | N23: =IF(Calc!$B$9=1,Calc!$C$9,"–") | T23: =IF(Calc!$B$9=1,Calc!$K$9,"–") | Z23: =IF(Calc!$B$9=1,Calc!$D$9,"–") | AF23: =IF(Calc!$B$9=1,Calc!$L$9,"–") | AL23: =IF(Calc!$B$9=1,Calc!$N$9,"–") | AR23: =IF(Calc!$B$9=1,Calc!$O$9,"–") | AX23: =IF(Calc!$B$9=1,Calc!$Q$9,"–")
D27: + | BE27: +
E28: =Calc!$B$58

Sheet Calc
A1: Calculation sheet — no inputs here
A2: Everything below is computed from Data (only rows 'In comparison' = 1).
A5: Product | B5: In scope | C5: Units CY | D5: Rev CY | E5: Units PY | F5: Rev PY | G5: Units PY eq-days | H5: Rev PY eq-days | I5: Head-start units | J5: Head-start rev | K5: Units Δ same date | L5: Rev Δ same date | M5: Units Δ equal days | N5: Rev Δ equal days | O5: Avg price CY | P5: Avg price PY | Q5: Price Δ
A6: =Control!B11 | B6: =IF(Control!C11="Yes",1,0) | C6: =SUMIFS(Dat_F,Dat_J,"CY",Dat_L,1,Dat_B,$A6) | D6: =SUMIFS(Dat_G,Dat_J,"CY",Dat_L,1,Dat_B,$A6) | E6: =SUMIFS(Dat_F,Dat_J,"PY",Dat_L,1,Dat_B,$A6) | F6: =SUMIFS(Dat_G,Dat_J,"PY",Dat_L,1,Dat_B,$A6) | G6: =SUMIFS(Dat_O,Dat_J,"PY",Dat_L,1,Dat_B,$A6) | H6: =SUMIFS(Dat_P,Dat_J,"PY",Dat_L,1,Dat_B,$A6) | I6: =SUMIFS(Dat_Q,Dat_J,"PY",Dat_L,1,Dat_B,$A6) | J6: =SUMIFS(Dat_R,Dat_J,"PY",Dat_L,1,Dat_B,$A6) | K6: =IF(E6>0,C6/E6-1,"n/a") | L6: =IF(F6>0,D6/F6-1,"n/a") | M6: =IF(G6>0,C6/G6-1,"n/a") | N6: =IF(H6>0,D6/H6-1,"n/a") | O6: =IF(C6>0,D6/C6,"n/a") | P6: =IF(E6>0,F6/E6,"n/a") | Q6: =IF(AND(ISNUMBER(O6),ISNUMBER(P6)),O6/P6-1,"n/a")
A7: =Control!B12 | B7: =IF(Control!C12="Yes",1,0) | C7: =SUMIFS(Dat_F,Dat_J,"CY",Dat_L,1,Dat_B,$A7) | D7: =SUMIFS(Dat_G,Dat_J,"CY",Dat_L,1,Dat_B,$A7) | E7: =SUMIFS(Dat_F,Dat_J,"PY",Dat_L,1,Dat_B,$A7) | F7: =SUMIFS(Dat_G,Dat_J,"PY",Dat_L,1,Dat_B,$A7) | G7: =SUMIFS(Dat_O,Dat_J,"PY",Dat_L,1,Dat_B,$A7) | H7: =SUMIFS(Dat_P,Dat_J,"PY",Dat_L,1,Dat_B,$A7) | I7: =SUMIFS(Dat_Q,Dat_J,"PY",Dat_L,1,Dat_B,$A7) | J7: =SUMIFS(Dat_R,Dat_J,"PY",Dat_L,1,Dat_B,$A7) | K7: =IF(E7>0,C7/E7-1,"n/a") | L7: =IF(F7>0,D7/F7-1,"n/a") | M7: =IF(G7>0,C7/G7-1,"n/a") | N7: =IF(H7>0,D7/H7-1,"n/a") | O7: =IF(C7>0,D7/C7,"n/a") | P7: =IF(E7>0,F7/E7,"n/a") | Q7: =IF(AND(ISNUMBER(O7),ISNUMBER(P7)),O7/P7-1,"n/a")
A8: =Control!B13 | B8: =IF(Control!C13="Yes",1,0) | C8: =SUMIFS(Dat_F,Dat_J,"CY",Dat_L,1,Dat_B,$A8) | D8: =SUMIFS(Dat_G,Dat_J,"CY",Dat_L,1,Dat_B,$A8) | E8: =SUMIFS(Dat_F,Dat_J,"PY",Dat_L,1,Dat_B,$A8) | F8: =SUMIFS(Dat_G,Dat_J,"PY",Dat_L,1,Dat_B,$A8) | G8: =SUMIFS(Dat_O,Dat_J,"PY",Dat_L,1,Dat_B,$A8) | H8: =SUMIFS(Dat_P,Dat_J,"PY",Dat_L,1,Dat_B,$A8) | I8: =SUMIFS(Dat_Q,Dat_J,"PY",Dat_L,1,Dat_B,$A8) | J8: =SUMIFS(Dat_R,Dat_J,"PY",Dat_L,1,Dat_B,$A8) | K8: =IF(E8>0,C8/E8-1,"n/a") | L8: =IF(F8>0,D8/F8-1,"n/a") | M8: =IF(G8>0,C8/G8-1,"n/a") | N8: =IF(H8>0,D8/H8-1,"n/a") | O8: =IF(C8>0,D8/C8,"n/a") | P8: =IF(E8>0,F8/E8,"n/a") | Q8: =IF(AND(ISNUMBER(O8),ISNUMBER(P8)),O8/P8-1,"n/a")
A9: Total | B9: 1 | C9: =SUMIFS(Dat_F,Dat_J,"CY",Dat_L,1) | D9: =SUMIFS(Dat_G,Dat_J,"CY",Dat_L,1) | E9: =SUMIFS(Dat_F,Dat_J,"PY",Dat_L,1) | F9: =SUMIFS(Dat_G,Dat_J,"PY",Dat_L,1) | G9: =SUMIFS(Dat_O,Dat_J,"PY",Dat_L,1) | H9: =SUMIFS(Dat_P,Dat_J,"PY",Dat_L,1) | I9: =SUMIFS(Dat_Q,Dat_J,"PY",Dat_L,1) | J9: =SUMIFS(Dat_R,Dat_J,"PY",Dat_L,1) | K9: =IF(E9>0,C9/E9-1,"n/a") | L9: =IF(F9>0,D9/F9-1,"n/a") | M9: =IF(G9>0,C9/G9-1,"n/a") | N9: =IF(H9>0,D9/H9-1,"n/a") | O9: =IF(C9>0,D9/C9,"n/a") | P9: =IF(E9>0,F9/E9,"n/a") | Q9: =IF(AND(ISNUMBER(O9),ISNUMBER(P9)),O9/P9-1,"n/a")
A12: Item | B12: Value
A13: report_date | B13: =IF(ISNUMBER(Control!C18),Control!C18,0)
A14: d_cy | B14: =IFERROR(_xlfn.MAXIFS(Dat_M,Dat_L,1),0)
A15: d_cy_min | B15: =IFERROR(_xlfn.MINIFS(Dat_M,Dat_L,1),0)
A16: d_py | B16: =IFERROR(_xlfn.MAXIFS(Dat_N,Dat_L,1),0)
A17: d_py_min | B17: =IFERROR(_xlfn.MINIFS(Dat_N,Dat_L,1),0)
A18: hs_days | B18: =Calc!$B$16-Calc!$B$14
A19: launch_cy_min | B19: =IFERROR(_xlfn.MINIFS(Dat_D,Dat_J,"CY",Dat_L,1),0)
A20: launch_cy_max | B20: =IFERROR(_xlfn.MAXIFS(Dat_D,Dat_J,"CY",Dat_L,1),0)
A21: launch_py_min | B21: =IFERROR(_xlfn.MINIFS(Dat_D,Dat_J,"PY",Dat_L,1),0)
A22: launch_py_max | B22: =IFERROR(_xlfn.MAXIFS(Dat_D,Dat_J,"PY",Dat_L,1),0)
A23: market | B23: =IF(Sel_Market="All markets","All markets",Sel_Market)
A24: gap_rev | B24: =Calc!$F$9-Calc!$D$9
A25: gap_units | B25: =Calc!$E$9-Calc!$C$9
A26: share_rev | B26: =IF(Calc!$B$24>0,Calc!$J$9/Calc!$B$24,"n/a")
A27: share_units | B27: =IF(Calc!$B$25>0,Calc!$I$9/Calc!$B$25,"n/a")
A28: gap_rev_eq | B28: =Calc!$B$24-Calc!$J$9
A29: gap_units_eq | B29: =Calc!$B$25-Calc!$I$9
A30: share_phrase | B30: =IF(ISNUMBER(Calc!$B$26),IF(ABS(Calc!$B$26-0.5)<=0.1,"half the revenue gap",ROUND(Calc!$B$26*100,0)&"% of the revenue gap"),"")
A31: multi_note | B31: =IF(OR(Calc!$B$14<>Calc!$B$15,Calc!$B$16<>Calc!$B$17)," Days shown are for the longest-running market; estimates are computed market by market.","")
A32: scope_raw | B32: =SUBSTITUTE(TRIM(IF($B$6=1,$A$6&" ","")&IF($B$7=1,$A$7&" ","")&IF($B$8=1,$A$8&" ",""))," ","|")
A33: scope_and | B33: =IF(LEN(Calc!$B$32)-LEN(SUBSTITUTE(Calc!$B$32,"|",""))=2,SUBSTITUTE(SUBSTITUTE(Calc!$B$32,"|",", ",1),"|"," and "),SUBSTITUTE(Calc!$B$32,"|"," and "))
A34: scope_plus | B34: =SUBSTITUTE(Calc!$B$32,"|"," + ")
A35: excl_raw | B35: =SUBSTITUTE(TRIM(IF($B$6=0,$A$6&" ","")&IF($B$7=0,$A$7&" ","")&IF($B$8=0,$A$8&" ",""))," ","|")
A36: excluded | B36: =IF(Calc!$B$35="","All products included",SUBSTITUTE(Calc!$B$35,"|"," and ")&" excluded")
A37: t_launch_cy | B37: =IF(Calc!$B$19=0,"n/a",IF(Calc!$B$19=Calc!$B$20,IF(Calc!$B$19=0,"n/a",DAY(Calc!$B$19)&" "&CHOOSE(MONTH(Calc!$B$19),"Jan","Feb","Mar","Apr","May","Jun","Jul","Aug","Sep","Oct","Nov","Dec")),IF(Calc!$B$19=0,"n/a",DAY(Calc!$B$19)&" "&CHOOSE(MONTH(Calc!$B$19),"Jan","Feb","Mar","Apr","May","Jun","Jul","Aug","Sep","Oct","Nov","Dec"))&" – "&IF(Calc!$B$20=0,"n/a",DAY(Calc!$B$20)&" "&CHOOSE(MONTH(Calc!$B$20),"Jan","Feb","Mar","Apr","May","Jun","Jul","Aug","Sep","Oct","Nov","Dec"))))
A38: t_launch_py | B38: =IF(Calc!$B$21=0,"n/a",IF(Calc!$B$21=Calc!$B$22,IF(Calc!$B$21=0,"n/a",DAY(Calc!$B$21)&" "&CHOOSE(MONTH(Calc!$B$21),"Jan","Feb","Mar","Apr","May","Jun","Jul","Aug","Sep","Oct","Nov","Dec")),IF(Calc!$B$21=0,"n/a",DAY(Calc!$B$21)&" "&CHOOSE(MONTH(Calc!$B$21),"Jan","Feb","Mar","Apr","May","Jun","Jul","Aug","Sep","Oct","Nov","Dec"))&" – "&IF(Calc!$B$22=0,"n/a",DAY(Calc!$B$22)&" "&CHOOSE(MONTH(Calc!$B$22),"Jan","Feb","Mar","Apr","May","Jun","Jul","Aug","Sep","Oct","Nov","Dec"))))
A39: t_report_short | B39: =IF(Calc!$B$13=0,"n/a",DAY(Calc!$B$13)&" "&CHOOSE(MONTH(Calc!$B$13),"Jan","Feb","Mar","Apr","May","Jun","Jul","Aug","Sep","Oct","Nov","Dec"))
A40: t_report_long | B40: =IF(Calc!$B$13=0,"",UPPER(DAY(Calc!$B$13)&" "&CHOOSE(MONTH(Calc!$B$13),"January","February","March","April","May","June","July","August","September","October","November","December")&" "&YEAR(Calc!$B$13)))
A41: k_cover_left | B41: =UPPER("Sales update · "&Calc!$B$23)
A42: k_cover_sub | B42: ="First results "&Yr_Cur&" vs "&Yr_Prev
A43: k_cover_scope | B43: ="Scope: "&Calc!$B$33
A44: k_cover_l1 | B44: ="Launch "&Yr_Cur&": "&Calc!$B$37
...
